### JavaScript - throw / how to use throw to invoke exceptions using Error object

- [error bubbling 과 handling에 대한 문서](https://developer.mozilla.org/en-US/docs/Web/JavaScript/Guide/Control_flow_and_error_handling)

the `throw` statement throws a user-defined exception.

Execution of the current function will _stop_ ( the statements after `throw` will not be executed ), and control will be passed to the first catch block in the call stack.

If no catch block exists among caller functions, the program will terminate.

The `throw` keyword can be followed by any kind of expression. (But must be followed by an expression) But in practice, the exception you throw should _always_ be an Error object or an instance of an `Error` subclass, such as `RangeError`.

→ WHY? This is because code that catches the error may expect certain properties, such as `message` to be on the caught value. ( 통상적으로 에러를 catch하는 코드 블럭에서 특정 property를 기대하고 있기 때문이라고 이해하였음. )

`throw new Error(’error!!’)` 라고 try블록에서 실행했을 때, catch block에 전달된 에러를 바로 콘솔에 찍으면 `Error: error!!` 라고 찍힌다. 이 때 : 으로 구분된 string 의 앞쪽, 즉 `Error` 는 error 객체의 name 프로퍼티에 해당되고 default로 ‘Error’ 임. 그리고 인스턴스 생성 시 constructor에 전달된 첫 번째 인자 string 이 바로 : 의 뒤쪽에 error!! 부분이다. 즉 가장 default로 에러 객체는 `error.name: error.message` 로 처리되어서 출력됨.

### 예외처리 - exception handling

예기치 못한 에러가 발생하였을 때, 이로부터 코드의 실행 흐름을 복구할 수 있는 기능. ( 내부적으로 call stack 이 어떻게 동작하는지 등 이어서 파악이 필요할 수 있음 )

코드의 실행 중에 에러가 발생하면, 코드의 실행이 중단되어 그 시점에 실행 중이었던 작업을 완료하지 못한다. JavaScript는 이런 상황에 프로그램을 바로 종료시키지 않고 이 에러를 필요한 형태로 처리한 후에 코드의 실행 흐름을 이어나갈 수 있도록 `try…catch…finally` 구문이 기능으로 제공된다.
