# async await

특정 상황에서 코드의 실행 흐름이 이해가 되지 않아서 공부해보았다.

async await, promise...등 키워드들에 대해서 이번에 깊게 파서 제대로 이해하고 쭉 써먹자.

## 이해되지 않는 코드

```javascript
// 비동기적으로 resolve되는 promise를 반환하는 함수
function returnPromise() {
  return new Promise((res, rej) => {
    setTimeout(() => {
      res("mock api call result");
    }, 2000);
  });
}

async function tryCatchAsyncFunc() {
  try {
    const result = await returnPromise();

    console.log("tryCatchAsyncFunc안에서 처리된 결과");
    console.log(result);
    console.log("");
  } catch (error) {
    console.log(error);
  }
}

function SomeComponentMock() {
  // 컴포넌트라고 치자..
  // 컴포넌트 안에서 try catch문으로 비동기 호출을 처리하는 함수를 호출하는 상황임

  const callResult = tryCatchAsyncFunc();
  console.log("동기적으로 함수 실행한 경우");
  console.log(callResult);
}

async function SomeComponentMock2() {
  const callResult = await tryCatchAsyncFunc();

  console.log("async await로 실행 함수를 감싼 경우");
  console.log(callResult);
  console.log("");
}

SomeComponentMock();
SomeComponentMock2();
```

근데 왜 tryCatchAsyncFunc 자체가 try-catch 내의 await 키워드로 execution이 멈춰있는데
SomeComponentMock처럼 tryCatchAsyncFunc 함수의 호출하는 코드 자체를 await키워드를 붙여서 처리하지 않으면 함수 실행이 멈추지 않고 끝나버리는걸까? 왜 해당 함수를 호출하는 코드 블록도 SomeComponentMock2처럼 async await를 통해서 처리를 해줘야할까?

이걸 이해하지 못하는 건 뭘 모르기 때문일까?

이 부분을 채워야 한다. 내일 아침에 대전 가야하니까 일단 자고 내일 대전가서 이어서 탐색해보자...

- Promise가 error와 함께 reject되는 경우에 대한 처리
- 아무것도 반환하지 않은 경우 Promise { undefined } 로 처리되는 부분에 대한 공부 (함수는 아무것도 반환하지 않으면 암시적으로 undefined를 반환하는데, async function은 `무조건` Promise를 반환하도록 설계되어 있음. Promise객체가 아닌 값을 반환해도 암시적으로 Promise로 감싸서 반환한다. 그래서 Promise {undefined}가 되지 않았을까 생각하는데 검증이 필요)
