# 내가 작성했던 코드의 문제점 정확하게 파악하기

에러 핸들링 코드를 작성하면서 뭔가 마음에 안들고 이게 맞나 싶었던 이유가 뭘까??

명확한 원인을 파악해야지 해결을 할 수 있다.

## 코드 simplified

특정 컴포넌트를 렌더링 할 때, 해당 컴포넌트에 콜백함수를 전달해서 그 컴포넌트가 수행하는 외부 특정 처리가 완료된 이후에 해당 콜백함수가 실행되는 구조에서,
콜백함수에서 처리된 값을 받아서,
그 값을 검증하기 위해서 필요한 일련의 프로세스를 구현하는 것이 목적

1. 처리된 값이 유효한 값이 검증하기 위한 데이터를 얻기 위한 api를 호출하기 위해서 액세스 토큰 발급
2. 액세스 토큰 값으로 api를 호출해서 처리된 값을 검증하기 위한 데이터를 얻기
3. 데이터 교차 검증
4. 여기까지 일련의 과정을 처리하는 함수 `complete()`로 로직을 묶고, 처리된 값을 반환
5. 반환된 값이 필요한 컴포넌트에서 `complete()` 함수를 호출해서 값을 받고, 해당 값이 유효한 값인 경우 처리될 로직을 담은 handler함수 호출
6. handler함수는 db에 값 저장하는 함수 호출하고, db저장이 성공 시 특정 화면으로 navigate하는 함수 호출

```javascript
// ---- someDataAPI.js 모듈 ----
// 이 라이브러리를 통해서 일련의 처리를 할 때 공통으로 사용될 것이라고 생각되는 함수들을 모듈로 빼서 구현
const tokenAPI = async () => {};
const dataAPI = async (data_id, accessToken) => {};

const getAccessToken = async () => {
  try {
    const result = await tokenAPI();
    // 액세스 토큰 발급 api 호출

    return result;
  } catch (error) {
    throw new Error("getAccessToken error", error);
  }
};

const getData = async (data_id, accessToken) => {
  try {
    const result = await dataAPI(data_id, accessToken);
    // 액세스 토큰 값으로 api를 호출해서 처리된 값을 검증하기 위한 데이터를 얻기

    return result;
  } catch (error) {
    throw new Error("getData error", error);
  }
};

const isDataValid = (fetchedData, validData) => {
  // 데이터 교차 검증
  return fetchedData === validData;
};

// 각 함수를 묶어서 실행하는 complete함수, 외부로 export해서 사용되는 형태
// 잘 처리되면 데이터를, 처리되지 않으면 null을 반환
export const complete = async (data_id, validData) => {
  try {
    // 데이터 조회, 각 단계에서 문제가 발생하는 경우 error throw 하도록 구현된 상태
    const accessToken = await getAccessToken();
    const fetchedData = await getData(data_id, accessToken);

    // 유효한 데이터인 경우 반환,
    if (isDataValid(fetchedData, validData)) {
      return fetchedData;
    }

    // 유효한 데이터 아닌 경우 에러 throw해서 catch block으로 이동
    throw new Error("invalid data");
  } catch (error) {
    throw new Error("complete error", error);
    return null;
  }
};

// ---- someDataAPI.js ----

// ---- SomeComponent.js ----

// someDataAPI의 complete함수를 호출해서 처리된 값을 받아서, 그 값이 유효한 값인 경우 처리될 로직을 담은 handler함수 호출하는 로직이 구현된 컴포넌트
// 처리하는 handler함수의 로직이 경우별로 다를 수 있다고 판단해서 successHandler는 모듈의 complete함수를 호출하는 컴포넌트 안에서 선언해서 사용하는 형태로 구현하였음.
const SomeComponent = () => {
  const validData = "valideDataValue";

  const saveData = async (data) => {
    // db에 값 저장하는 로직
  };

  const successHandler = async (data) => {
    // db에 값 저장하는 함수 호출
    // db저장이 성공 시 특정 화면으로 navigate하는 함수 호출
    try {
      const savedData = await saveData(data);

      if (savedData) {
        // 성공에 따라 필요한 처리,
        // 여기까지 성공하면 다 잘 처리되었음.
      } else {
        throw new Error("saveData failed");
      }
    } catch (error) {
      console.log("successHandler error", error);
      // 필요한 처리
    }
  };
  // 라이브러리 모듈에 전달하는 함수
  const callback = async (response) => {
    try {
      if (response.success === true) {
        const result = await complete(response.data_id, validData);

        if (result) {
          successHandler(result);
        } else {
          throw new Error("complete failed");
        }
      }
    } catch (error) {
      console.log("callback error", error);
      // 오류에 따른 처리
    }
  };

  return <SomeModule callback={callback} />;
};

// ---- SomeComponent.js ----
```

## 문제라고 생각되는 포인트

- `someDataAPI.js`모듈에서 `complete`함수의 catch블록에서 각 단계별 함수의 catch블록에서 throw한 예외를 한 번에 처리하는 구조 이거 괜찮은지 모르겠음. 코드를 모르는 사람이 봤을 때 이해가 직관적으로 되는 코드일까? 그리고 기능적으로 놓치는 부분이 없는 코드인걸까?

- `SomeComponent.js`에서 `successHandler`함수와 `callback`함수가 각각 뭔가 또 막 error throw 하고, try-catch블록이랑 안에서 또 if로 조건분기 쳐있고 이러니까 기본적으로 코드가 깔끔한 느낌이 안드는 것도 문제고, 흐름이 한 눈에 들어오지 않는 느낌을 받은 듯 하다.

- 더 graceful하게 코드를 처리하는 방법이 없을까?? 아니면 이런 형태는 어쩔 수 없는걸까?

- 위 코드의 문제
  - 가독성이 떨어진다고 생각됨 (흐름 파악이 쉽지 않음)
  - 비동기 호출에 대한 에러가 제대로 처리될 것인지 보장을 못하겠음 내가.
