# 어제에 이어서, 내 에러 핸들링 관련 코드를 개선해보자.

## 걱정했던 이슈들

- `someDataAPI.js`모듈에서 `complete`함수의 catch블록에서 각 단계별 함수의 catch블록에서 throw한 예외를 한 번에 처리하는 구조 이거 괜찮은지 모르겠음. 코드를 모르는 사람이 봤을 때 이해가 직관적으로 되는 코드일까? 그리고 기능적으로 놓치는 부분이 없는 코드인걸까?

- `SomeComponent.js`에서 `successHandler`함수와 `callback`함수가 각각 뭔가 또 막 error throw 하고, try-catch블록이랑 안에서 또 if로 조건분기 쳐있고 이러니까 기본적으로 코드가 깔끔한 느낌이 안드는 것도 문제고, 흐름이 한 눈에 들어오지 않는 느낌을 받은 듯 하다.

- 더 graceful하게 코드를 처리하는 방법이 없을까?? 아니면 이런 형태는 어쩔 수 없는걸까?

- 가독성이 떨어진다고 생각됨 (흐름 파악이 쉽지 않음)
- 비동기 호출에 대한 에러가 제대로 처리될 것인지 보장을 못하겠음 내가.

## 문제 하나씩 살펴보기.

### 가독성 이슈

내 코드를 처음보는 사람이 이해하기 힘들만한 부분이 뭘까??

- 에러처리가 각 함수안에서 바로 되는 것이 아니라 throw 하는 형태로 처리되어서 최종 `complete`함수의 catch block에서 처리된다는 점 -> nested try catch 블록 구조인게 별로인 것처럼 느껴짐..

  - 애초에 nested try catch 가 필요한지? 그냥 각 함수의 로직은 try catch 로 처리하지 않아도 되지 않는지?

- `complete`함수 안에서도 별개로 에러 발생할 수 있는 나름의 부분이 존재한다는 점..

#### nested try catch block의 필요성이 있는지??

```javascript
// 개별 함수 내에서 비동기 호출을 try catch 블록안에서 처리하지 않아도 마지막에 모아서 실행하는 함수에서 try catch 안에서 코드를 실행하면 에러가 처리된다.

// 비동기적으로 데이터 호출하는 함수 mock
const apicallMock = async (shouldError) => {
  return new Promise((resolve, reject) => {
    setTimeout(() => {
      if (shouldError) {
        return reject("apicallMock Error");
      }
      resolve("data");
    }, 5);
  });
};

const actionA = async () => {
  return await apicallMock(true);
};

const actionB = async () => {
  return await apicallMock(false);
};

// 묶어서 호출
(async () => {
  try {
    const a = await actionA();
    console.log(a);
    const b = await actionB();
    console.log(b);
  } catch (error) {
    console.log("IIFE error", error);
  }
})();
```

개별 함수를 try catch 블록안에서 처리하지 않아도 해당 함수의 호출을 감싸는 try catch 블록이 존재한다면 에러는 잡힌다. (아마 call stack에 catch가 있는지 찾는다는 개념이 여기서 적용될 듯 하다.)

마찬가지로, 해당 함수를 호출하고 catch() 메서드로 체이닝해도 될 듯?

근데 이렇게 처리했을 때 단점은, api에서 반환하는 에러 메세지가 명확하지 않을 때 에러가 어떤 함수에서 발생했는지 tracking이 어렵지 않을까 싶다.

그러면, try catch block을 nesting하지 않으면서 각 함수에서 발생한 에러를 어떻게 함수에 묶어서 처리할 수 있을까?

```javascript
// 아래처럼 처리하면?
// 묶어서 호출
(async () => {
  try {
    const a = await actionA().catch((error) => {
      throw new Error("actionA error");
    });
    console.log(a);
    const b = await actionB().catch((error) => {
      throw new Error("actionB error");
    });
    console.log(b);
  } catch (error) {
    console.log("IIFE error", error);
  }
})();
```

`IIFE error Error: actionA error `라고 찍혀서, 조금 더 구분할 여지가 생긴다 이렇게 하면.

근데 nested try catch 블록과, 이 방법 사이에서 어떤 방법이 더 코드 가독성이 좋을까?

error throwing이 하나의 함수에 너무 여러번 반복되면 이것도 보기가 좋지는 않을 듯 하다.

흠... 어렵네 ㅠㅠ
